2024-11-23 13:57:26,270 ERROR: Full error: Traceback (most recent call last):
  File "/mnt/c/Users/m/Desktop/web-based excel/custom-excel-app/backend/venv/lib/python3.12/site-packages/sqlalchemy/engine/base.py", line 3212, in _wrap_pool_connect
    return fn()
           ^^^^
  File "/mnt/c/Users/m/Desktop/web-based excel/custom-excel-app/backend/venv/lib/python3.12/site-packages/sqlalchemy/pool/base.py", line 307, in connect
    return _ConnectionFairy._checkout(self)
           ^^^^^^^^^^^^^^^^^^^^^^^^^^^^^^^^
  File "/mnt/c/Users/m/Desktop/web-based excel/custom-excel-app/backend/venv/lib/python3.12/site-packages/sqlalchemy/pool/base.py", line 767, in _checkout
    fairy = _ConnectionRecord.checkout(pool)
            ^^^^^^^^^^^^^^^^^^^^^^^^^^^^^^^^
  File "/mnt/c/Users/m/Desktop/web-based excel/custom-excel-app/backend/venv/lib/python3.12/site-packages/sqlalchemy/pool/base.py", line 425, in checkout
    rec = pool._do_get()
          ^^^^^^^^^^^^^^
  File "/mnt/c/Users/m/Desktop/web-based excel/custom-excel-app/backend/venv/lib/python3.12/site-packages/sqlalchemy/pool/impl.py", line 145, in _do_get
    with util.safe_reraise():
  File "/mnt/c/Users/m/Desktop/web-based excel/custom-excel-app/backend/venv/lib/python3.12/site-packages/sqlalchemy/util/langhelpers.py", line 70, in __exit__
    compat.raise_(
  File "/mnt/c/Users/m/Desktop/web-based excel/custom-excel-app/backend/venv/lib/python3.12/site-packages/sqlalchemy/util/compat.py", line 207, in raise_
    raise exception
  File "/mnt/c/Users/m/Desktop/web-based excel/custom-excel-app/backend/venv/lib/python3.12/site-packages/sqlalchemy/pool/impl.py", line 143, in _do_get
    return self._create_connection()
           ^^^^^^^^^^^^^^^^^^^^^^^^^
  File "/mnt/c/Users/m/Desktop/web-based excel/custom-excel-app/backend/venv/lib/python3.12/site-packages/sqlalchemy/pool/base.py", line 253, in _create_connection
    return _ConnectionRecord(self)
           ^^^^^^^^^^^^^^^^^^^^^^^
  File "/mnt/c/Users/m/Desktop/web-based excel/custom-excel-app/backend/venv/lib/python3.12/site-packages/sqlalchemy/pool/base.py", line 368, in __init__
    self.__connect()
  File "/mnt/c/Users/m/Desktop/web-based excel/custom-excel-app/backend/venv/lib/python3.12/site-packages/sqlalchemy/pool/base.py", line 610, in __connect
    with util.safe_reraise():
  File "/mnt/c/Users/m/Desktop/web-based excel/custom-excel-app/backend/venv/lib/python3.12/site-packages/sqlalchemy/util/langhelpers.py", line 70, in __exit__
    compat.raise_(
  File "/mnt/c/Users/m/Desktop/web-based excel/custom-excel-app/backend/venv/lib/python3.12/site-packages/sqlalchemy/util/compat.py", line 207, in raise_
    raise exception
  File "/mnt/c/Users/m/Desktop/web-based excel/custom-excel-app/backend/venv/lib/python3.12/site-packages/sqlalchemy/pool/base.py", line 605, in __connect
    connection = pool._invoke_creator(self)
                 ^^^^^^^^^^^^^^^^^^^^^^^^^^
  File "/mnt/c/Users/m/Desktop/web-based excel/custom-excel-app/backend/venv/lib/python3.12/site-packages/sqlalchemy/engine/create.py", line 578, in connect
    return dialect.connect(*cargs, **cparams)
           ^^^^^^^^^^^^^^^^^^^^^^^^^^^^^^^^^^
  File "/mnt/c/Users/m/Desktop/web-based excel/custom-excel-app/backend/venv/lib/python3.12/site-packages/sqlalchemy/engine/default.py", line 584, in connect
    return self.dbapi.connect(*cargs, **cparams)
           ^^^^^^^^^^^^^^^^^^^^^^^^^^^^^^^^^^^^^
  File "/mnt/c/Users/m/Desktop/web-based excel/custom-excel-app/backend/venv/lib/python3.12/site-packages/psycopg2/__init__.py", line 122, in connect
    conn = _connect(dsn, connection_factory=connection_factory, **kwasync)
           ^^^^^^^^^^^^^^^^^^^^^^^^^^^^^^^^^^^^^^^^^^^^^^^^^^^^^^^^^^^^^^^
psycopg2.OperationalError: could not translate host name "dpg-cssok43tq21c73a38p0g-a" to address: Name or service not known


The above exception was the direct cause of the following exception:

Traceback (most recent call last):
  File "/mnt/c/Users/m/Desktop/web-based excel/custom-excel-app/backend/app.py", line 81, in log_request_info
    db.session.execute('SELECT 1')
  File "<string>", line 2, in execute
  File "/mnt/c/Users/m/Desktop/web-based excel/custom-excel-app/backend/venv/lib/python3.12/site-packages/sqlalchemy/orm/session.py", line 1688, in execute
    conn = self._connection_for_bind(bind)
           ^^^^^^^^^^^^^^^^^^^^^^^^^^^^^^^
  File "/mnt/c/Users/m/Desktop/web-based excel/custom-excel-app/backend/venv/lib/python3.12/site-packages/sqlalchemy/orm/session.py", line 1529, in _connection_for_bind
    return self._transaction._connection_for_bind(
           ^^^^^^^^^^^^^^^^^^^^^^^^^^^^^^^^^^^^^^^
  File "/mnt/c/Users/m/Desktop/web-based excel/custom-excel-app/backend/venv/lib/python3.12/site-packages/sqlalchemy/orm/session.py", line 747, in _connection_for_bind
    conn = bind.connect()
           ^^^^^^^^^^^^^^
  File "/mnt/c/Users/m/Desktop/web-based excel/custom-excel-app/backend/venv/lib/python3.12/site-packages/sqlalchemy/engine/base.py", line 3166, in connect
    return self._connection_cls(self, close_with_result=close_with_result)
           ^^^^^^^^^^^^^^^^^^^^^^^^^^^^^^^^^^^^^^^^^^^^^^^^^^^^^^^^^^^^^^^
  File "/mnt/c/Users/m/Desktop/web-based excel/custom-excel-app/backend/venv/lib/python3.12/site-packages/sqlalchemy/engine/base.py", line 96, in __init__
    else engine.raw_connection()
         ^^^^^^^^^^^^^^^^^^^^^^^
  File "/mnt/c/Users/m/Desktop/web-based excel/custom-excel-app/backend/venv/lib/python3.12/site-packages/sqlalchemy/engine/base.py", line 3245, in raw_connection
    return self._wrap_pool_connect(self.pool.connect, _connection)
           ^^^^^^^^^^^^^^^^^^^^^^^^^^^^^^^^^^^^^^^^^^^^^^^^^^^^^^^
  File "/mnt/c/Users/m/Desktop/web-based excel/custom-excel-app/backend/venv/lib/python3.12/site-packages/sqlalchemy/engine/base.py", line 3215, in _wrap_pool_connect
    Connection._handle_dbapi_exception_noconnection(
  File "/mnt/c/Users/m/Desktop/web-based excel/custom-excel-app/backend/venv/lib/python3.12/site-packages/sqlalchemy/engine/base.py", line 2069, in _handle_dbapi_exception_noconnection
    util.raise_(
  File "/mnt/c/Users/m/Desktop/web-based excel/custom-excel-app/backend/venv/lib/python3.12/site-packages/sqlalchemy/util/compat.py", line 207, in raise_
    raise exception
  File "/mnt/c/Users/m/Desktop/web-based excel/custom-excel-app/backend/venv/lib/python3.12/site-packages/sqlalchemy/engine/base.py", line 3212, in _wrap_pool_connect
    return fn()
           ^^^^
  File "/mnt/c/Users/m/Desktop/web-based excel/custom-excel-app/backend/venv/lib/python3.12/site-packages/sqlalchemy/pool/base.py", line 307, in connect
    return _ConnectionFairy._checkout(self)
           ^^^^^^^^^^^^^^^^^^^^^^^^^^^^^^^^
  File "/mnt/c/Users/m/Desktop/web-based excel/custom-excel-app/backend/venv/lib/python3.12/site-packages/sqlalchemy/pool/base.py", line 767, in _checkout
    fairy = _ConnectionRecord.checkout(pool)
            ^^^^^^^^^^^^^^^^^^^^^^^^^^^^^^^^
  File "/mnt/c/Users/m/Desktop/web-based excel/custom-excel-app/backend/venv/lib/python3.12/site-packages/sqlalchemy/pool/base.py", line 425, in checkout
    rec = pool._do_get()
          ^^^^^^^^^^^^^^
  File "/mnt/c/Users/m/Desktop/web-based excel/custom-excel-app/backend/venv/lib/python3.12/site-packages/sqlalchemy/pool/impl.py", line 145, in _do_get
    with util.safe_reraise():
  File "/mnt/c/Users/m/Desktop/web-based excel/custom-excel-app/backend/venv/lib/python3.12/site-packages/sqlalchemy/util/langhelpers.py", line 70, in __exit__
    compat.raise_(
  File "/mnt/c/Users/m/Desktop/web-based excel/custom-excel-app/backend/venv/lib/python3.12/site-packages/sqlalchemy/util/compat.py", line 207, in raise_
    raise exception
  File "/mnt/c/Users/m/Desktop/web-based excel/custom-excel-app/backend/venv/lib/python3.12/site-packages/sqlalchemy/pool/impl.py", line 143, in _do_get
    return self._create_connection()
           ^^^^^^^^^^^^^^^^^^^^^^^^^
  File "/mnt/c/Users/m/Desktop/web-based excel/custom-excel-app/backend/venv/lib/python3.12/site-packages/sqlalchemy/pool/base.py", line 253, in _create_connection
    return _ConnectionRecord(self)
           ^^^^^^^^^^^^^^^^^^^^^^^
  File "/mnt/c/Users/m/Desktop/web-based excel/custom-excel-app/backend/venv/lib/python3.12/site-packages/sqlalchemy/pool/base.py", line 368, in __init__
    self.__connect()
  File "/mnt/c/Users/m/Desktop/web-based excel/custom-excel-app/backend/venv/lib/python3.12/site-packages/sqlalchemy/pool/base.py", line 610, in __connect
    with util.safe_reraise():
  File "/mnt/c/Users/m/Desktop/web-based excel/custom-excel-app/backend/venv/lib/python3.12/site-packages/sqlalchemy/util/langhelpers.py", line 70, in __exit__
    compat.raise_(
  File "/mnt/c/Users/m/Desktop/web-based excel/custom-excel-app/backend/venv/lib/python3.12/site-packages/sqlalchemy/util/compat.py", line 207, in raise_
    raise exception
  File "/mnt/c/Users/m/Desktop/web-based excel/custom-excel-app/backend/venv/lib/python3.12/site-packages/sqlalchemy/pool/base.py", line 605, in __connect
    connection = pool._invoke_creator(self)
                 ^^^^^^^^^^^^^^^^^^^^^^^^^^
  File "/mnt/c/Users/m/Desktop/web-based excel/custom-excel-app/backend/venv/lib/python3.12/site-packages/sqlalchemy/engine/create.py", line 578, in connect
    return dialect.connect(*cargs, **cparams)
           ^^^^^^^^^^^^^^^^^^^^^^^^^^^^^^^^^^
  File "/mnt/c/Users/m/Desktop/web-based excel/custom-excel-app/backend/venv/lib/python3.12/site-packages/sqlalchemy/engine/default.py", line 584, in connect
    return self.dbapi.connect(*cargs, **cparams)
           ^^^^^^^^^^^^^^^^^^^^^^^^^^^^^^^^^^^^^
  File "/mnt/c/Users/m/Desktop/web-based excel/custom-excel-app/backend/venv/lib/python3.12/site-packages/psycopg2/__init__.py", line 122, in connect
    conn = _connect(dsn, connection_factory=connection_factory, **kwasync)
           ^^^^^^^^^^^^^^^^^^^^^^^^^^^^^^^^^^^^^^^^^^^^^^^^^^^^^^^^^^^^^^^
sqlalchemy.exc.OperationalError: (psycopg2.OperationalError) could not translate host name "dpg-cssok43tq21c73a38p0g-a" to address: Name or service not known

(Background on this error at: https://sqlalche.me/e/14/e3q8)
 [in /mnt/c/Users/m/Desktop/web-based excel/custom-excel-app/backend/app.py:85]
